Workbook

Sheet RAW DATA - DO NOT EDIT
A1: Enrollment_ID | B1: Enrollment_Date | C1: Company | D1: Course_Category | E1: Course_Name | F1: City | G1: State | H1: City_Tier | I1: Gender | J1: Age_Group | K1: Referral_Source | L1: Payment_Mode | M1: Device_Type | N1: Original_Price_INR | O1: Discount_% | P1: Discount_Amount_INR | Q1: Final_Price_INR | R1: GST_Amount_INR | S1: Net_Revenue_INR | T1: Platform_Cost_INR | U1: Gross_Profit_INR | V1: Gross_Margin_% | W1: Course_Completed | X1: Student_Rating | Y1: Refund_Issued | Z1: Support_Tickets_Raised
A2: EDU00524 | B2: 08-11-2023 | C2: Embibe | D2: Coding & Tech | E2: Python for Beginners | F2: Jodhpur | G2: Rajasthan | H2: Tier 3 | I2: Male | J2: 25-34 | K2: Google Ads | L2: Debit Card | M2: Desktop | N2: 7999 | O2: 40 | P2: 3199.6 | Q2: 4799.4 | R2: 863.89 | S2: 3935.51 | T2: 2203.97 | U2: 1731.54 | V2: 44 | W2: Yes | X2: 4.6 | Y2: No | Z2: 1
A3: EDU00061 | B3: 05-12-2023 | C3: Meritnation | D3: Test Preparation | E3: GRE Verbal+Quant | F3: Mangaluru | G3: Karnataka | H3: Tier 3 | I3: Male | J3: 25-34 | K3: Instagram | L3: Wallet | M3: Tablet | N3: 11999 | O3: 10 | P3: 1199.9 | Q3: 10799.1 | R3: 1943.84 | S3: 8855.26 | T3: 3836.62 | U3: 5018.64 | V3: 56.67 | W3: Yes | X3: 4 | Y3: No | Z3: 0
A4: EDU00457 | B4: 15-12-2024 | C4: Embibe | D4: Higher Education | E4: MBA Finance Prep | F4: Ghaziabad | G4: Delhi NCR | H4: Tier 2 | I4: Other | J4: 18-24 | K4: Word of Mouth | L4: Credit Card | M4: Mobile | N4: 11999 | O4: 25 | P4: 2999.75 | Q4: 8999.25 | R4: 1619.87 | S4: 7379.38 | T4: 3191.83 | U4: 4187.55 | V4: 56.75 | W4: Yes | X4: 3.6 | Y4: No | Z4: 0
A5: EDU01052 | B5: 29-08-2024 | C5: Toppr | D5: Test Preparation | E5: SAT Complete Prep | F5: Ahmedabad | G5: Gujarat | H5: Tier 1 | I5: Male | J5: 13-17 | K5: YouTube | L5: Credit Card | M5: Mobile | N5: 12999 | O5: 0 | P5: 0 | Q5: 12999 | R5: 2339.82 | S5: 10659.18 | T5: 3738.71 | U5: 6920.47 | V5: 64.92 | W5: Yes | X5: 3.7 | Y5: No | Z5: 1
A6: EDU00891 | B6: 09-02-2023 | C6: Vedantu | D6: Test Preparation | E6: SAT Complete Prep | F6: Kolkata | G6: West Bengal | H6: Tier 1 | I6: Other | J6: 35-44 | K6: Google Ads | L6: Debit Card | M6: Desktop | N6: 12999 | O6: 40 | P6: 5199.6 | Q6: 7799.4 | R6: 1403.89 | S6: 6395.51 | T6: 3376.69 | U6: 3018.82 | V6: 47.2 | W6: Yes | X6: 3.6 | Y6: No | Z6: 0
A7: EDU01966 | B7: 12-01-2023 | C7: Toppr | D7: Professional Upskilling | E7: Digital Marketing Pro | F7: Gurugram | G7: Delhi NCR | H7: Tier 1 | I7: Female | J7: 25-34 | K7: WhatsApp | L7: EMI | M7: Mobile | N7: 12999 | O7: 0 | P7: 0 | Q7: 12999 | R7: 2339.82 | S7: 10659.18 | T7: 3264.37 | U7: 7394.81 | V7: 69.38 | W7: Yes | X7: 4.5 | Y7: No | Z7: 1
A8: EDU00027 | B8: 03-11-2023 | C8: BYJU'S | D8: Higher Education | E8: MBA Finance Prep | F8: Vadodara | G8: Gujarat | H8: Tier 3 | I8: Male | J8: 25-34 | K8: School/College Partnership | L8: EMI | M8: Mobile | N8: 11999 | O8: 0 | P8: 0 | Q8: 11999 | R8: 2159.82 | S8: 9839.18 | T8: 4348.29 | U8: 5490.89 | V8: 55.81 | W8: No | Y8: No | Z8: 1
A9: EDU00427 | B9: 18-01-2024 | C9: upGrad | D9: Creative Arts | E9: Video Editing Basics | F9: Pune | G9: Maharashtra | H9: Tier 1 | I9: Female | J9: 35-44 | K9: Word of Mouth | L9: Debit Card | M9: Mobile | N9: 6999 | O9: 5 | P9: 349.95 | Q9: 6649.05 | R9: 1196.83 | S9: 5452.22 | T9: 2206.78 | U9: 3245.44 | V9: 59.53 | W9: Yes | X9: 2.9 | Y9: No | Z9: 2
A10: EDU01634 | B10: 16-01-2023 | C10: Physics Wallah | D10: Creative Arts | E10: UI/UX Design | F10: Warangal | G10: Telangana | H10: Tier 3 | I10: Male | J10: 35-44 | K10: Direct/Organic | L10: EMI | M10: Mobile | N10: 14999 | O10: 25 | P10: 3749.75 | Q10: 11249.25 | R10: 2024.87 | S10: 9224.38 | T10: 4357.82 | U10: 4866.56 | V10: 52.76 | W10: No | Y10: No | Z10: 1
A11: EDU00833 | B11: 03-11-2024 | C11: Vedantu | D11: Higher Education | E11: MBA Finance Prep | F11: Madurai | G11: Tamil Nadu | H11: Tier 3 | I11: Other | J11: 18-24 | K11: Instagram | L11: Credit Card | M11: Desktop | N11: 11999 | O11: 50 | P11: 5999.5 | Q11: 5999.5 | R11: 1079.91 | S11: 4919.59 | T11: 2534.61 | U11: 2384.98 | V11: 48.48 | W11: No | Y11: No | Z11: 0
A12: EDU02161 | B12: 15-11-2023 | C12: Toppr | D12: Test Preparation | E12: SAT Complete Prep | F12: NOIDA | G12: Delhi NCR | H12: Tier 1 | I12: Male | J12: 18-24 | K12: Email Campaign | L12: UPI | M12: Mobile | N12: 12999 | O12: 40 | P12: 5199.6 | Q12: 7799.4 | R12: 1403.89 | S12: 6395.51 | T12: 2933.31 | U12: 3462.2 | V12: 54.13 | W12: No | Y12: Yes | Z12: 1
A13: EDU01493 | B13: 19-02-2024 | C13: Embibe | D13: Higher Education | E13: B.Tech CSE Support | F13: Warangal | G13: Telangana | H13: Tier 3 | I13: Male | J13: 13-17 | K13: YouTube | L13: Credit Card | M13: Mobile | N13: 9999 | O13: 10 | P13: 999.9 | Q13: 8999.1 | R13: 1619.84 | S13: 7379.26 | T13: 3528.47 | U13: 3850.79 | V13: 52.18 | W13: No | Y13: No | Z13: 1
A14: EDU02280 | B14: 14-10-2023 | C14: Simplilearn | D14: Professional Upskilling | E14: Digital Marketing Pro | F14: Mysuru | G14: Karnataka | H14: Tier 2 | I14: Female | J14: 25-34 | K14: WhatsApp | L14: EMI | M14: Desktop | N14: 12999 | O14: 20 | P14: 2599.8 | Q14: 10399.2 | R14: 1871.86 | S14: 8527.34 | T14: 3512.35 | U14: 5014.99 | V14: 58.81 | W14: No | Y14: No | Z14: 1
A15: EDU00700 | B15: 02-11-2023 | C15: BYJU'S | D15: Language Learning | E15: English Communication | F15: Chennai | G15: Tamil Nadu | H15: Tier 1 | I15: Male | J15: 13-17 | K15: Word of Mouth | L15: Credit Card | M15: Tablet | N15: 4999 | O15: 15 | P15: 749.85 | Q15: 4249.15 | R15: 764.85 | S15: 3484.3 | T15: 1347.82 | U15: 2136.48 | V15: 61.32 | W15: No | Y15: No | Z15: 3
A16: EDU02121 | B16: 21-12-2024 | C16: Great Learning | D16: Coding & Tech | E16: Full Stack Development | F16: Bengaluru | G16: Karnataka | H16: Tier 1 | I16: Female | J16: 45+ | K16: Direct/Organic | L16: UPI | M16: Tablet | N16: 29999 | O16: 40 | P16: 11999.6 | Q16: 17999.4 | R16: 3239.89 | S16: 14759.51 | T16: 6414.9 | U16: 8344.61 | V16: 56.54 | W16: Yes | X16: 4.2 | Y16: No | Z16: 0
A17: EDU00341 | B17: 10-11-2024 | C17: Doubtnut | D17: Creative Arts | E17: Graphic Design Pro | F17: Vadodara | G17: Gujarat | H17: Tier 3 | I17: Male | J17: 18-24 | K17: Direct/Organic | L17: Net Banking | M17: Mobile | N17: 9999 | O17: 25 | P17: 2499.75 | Q17: 7499.25 | R17: 1349.87 | S17: 6149.38 | T17: 2274.96 | U17: 3874.42 | V17: 63.01 | W17: No | Y17: No | Z17: 3
A18: EDU02148 | B18: 20-11-2023 | C18: Extramarks | D18: Test Preparation | E18: SAT Complete Prep | F18: Nashik | G18: Maharashtra | H18: Tier 2 | I18: Female | J18: 35-44 | K18: Email Campaign | L18: Wallet | M18: Desktop | N18: 12999 | O18: 40 | P18: 5199.6 | Q18: 7799.4 | R18: 1403.89 | S18: 6395.51 | T18: 3570.77 | U18: 2824.74 | V18: 44.17 | W18: No | Y18: No | Z18: 0
A19: EDU00152 | B19: 24-11-2023 | C19: Simplilearn | D19: Competitive Exams | E19: GATE CS Complete | F19: Vadodara | G19: Gujarat | H19: Tier 3 | I19: Male | J19: 18-24 | K19: Email Campaign | L19: EMI | M19: Mobile | N19: 12999 | O19: 25 | P19: 3249.75 | Q19: 9749.25 | R19: 1754.87 | S19: 7994.38 | T19: 3501.87 | U19: 4492.51 | V19: 56.2 | W19: Yes | Y19: No | Z19: 0
A20: EDU01163 | B20: 15-06-2024 | C20: BYJU'S | D20: Language Learning | E20: Business English | F20: Nashik | G20: Maharashtra | H20: Tier 2 | I20: Male | J20: 18-24 | K20: Direct/Organic | L20: UPI | M20: Mobile | N20: 6999 | O20: 40 | P20: 2799.6 | Q20: 4199.4 | R20: 755.89 | S20: 3443.51 | T20: 1857.34 | U20: 1586.17 | V20: 46.06 | W20: Yes | X20: 4 | Y20: No | Z20: 0
A21: EDU02226 | B21: 19-05-2023 | C21: BYJU'S | D21: Coding & Tech | E21: Python for Beginners | F21: Jaipur | G21: Rajasthan | H21: Tier 2 | I21: Male | J21: 18-24 | K21: Instagram | L21: Debit Card | M21: Mobile | N21: 7999 | O21: 0 | P21: 0 | Q21: 7999 | R21: 1439.82 | S21: 6559.18 | T21: 2831.55 | U21: 3727.63 | V21: 56.83 | W21: Yes | X21: 4.3 | Y21: No | Z21: 0
A22: EDU02334 | B22: 25-07-2024 | C22: BYJU'S | D22: Coding & Tech | E22: Full Stack Development | F22: Howrah | G22: West Bengal | H22: Tier 3 | I22: Female | J22: 25-34 | K22: Google Ads | L22: Wallet | M22: Mobile | N22: 29999 | O22: 40 | P22: 11999.6 | Q22: 17999.4 | R22: 3239.89 | S22: 14759.51 | T22: 7295.56 | U22: 7463.95 | V22: 50.57 | W22: Yes | Y22: No | Z22: 0
A23: EDU00808 | B23: 09-10-2023 | C23: Doubtnut | D23: Test Preparation | E23: GRE Verbal+Quant | F23: Surat | G23: Gujarat | H23: Tier 2 | I23: Female | J23: 45+ | K23: Word of Mouth | L23: UPI | M23: Tablet | N23: 11999 | O23: 0 | P23: 0 | Q23: 11999 | R23: 2159.82 | S23: 9839.18 | T23: 4634.06 | U23: 5205.12 | V23: 52.9 | W23: Yes | X23: 3.1 | Y23: No | Z23: 2
A24: EDU01261 | B24: 14-01-2024 | C24: Great Learning | D24: Competitive Exams | E24: IIT-JEE Advanced Prep | F24: Howrah | G24: West Bengal | H24: Tier 3 | I24: Female | J24: 18-24 | K24: Email Campaign | L24: Wallet | M24: Desktop | N24: 24999 | O24: 20 | P24: 4999.8 | Q24: 19999.2 | R24: 3599.86 | S24: 16399.34 | T24: 6763.99 | U24: 9635.35 | V24: 58.75 | W24: Yes | X24: 3.7 | Y24: No | Z24: 0
A25: EDU01083 | B25: 17-06-2023 | C25: Doubtnut | D25: Competitive Exams | E25: CAT Prep Masterclass | F25: Chennai | G25: Tamil Nadu | H25: Tier 1 | I25: Other | J25: 35-44 | K25: Google Ads | L25: Credit Card | M25: Desktop | N25: 14999 | O25: 0 | P25: 0 | Q25: 14999 | R25: 2699.82 | S25: 12299.18 | T25: 4245.97 | U25: 8053.21 | V25: 65.48 | W25: Yes | X25: 3.4 | Y25: No | Z25: 0
A26: EDU00326 | B26: 05-01-2023 | C26: Meritnation | D26: Professional Upskilling | E26: Digital Marketing Pro | F26: Surat | G26: Gujarat | H26: Tier 2 | I26: Male | J26: 35-44 | K26: School/College Partnership | L26: Credit Card | M26: Mobile | N26: 12999 | O26: 50 | P26: 6499.5 | Q26: 6499.5 | R26: 1169.91 | S26: 5329.59 | T26: 2783.75 | U26: 2545.84 | V26: 47.77 | W26: No | Y26: No | Z26: 1
A27: EDU00465 | B27: 27-05-2024 | C27: Scaler | D27: K-12 Academics | E27: Class 8-10 Science Pack | F27: Madurai | G27: Tamil Nadu | H27: Tier 3 | I27: Female | J27: 35-44 | K27: YouTube | L27: UPI | M27: Desktop | N27: 4999 | O27: 5 | P27: 249.95 | Q27: 4749.05 | R27: 854.83 | S27: 3894.22 | T27: 2019.87 | U27: 1874.35 | V27: 48.13 | W27: No | Y27: No | Z27: 1
A28: EDU00745 | B28: 12-05-2023 | C28: Meritnation | D28: K-12 Academics | E28: Foundation Course | F28: Bengaluru | G28: Karnataka | H28: Tier 1 | I28: Female | J28: 35-44 | K28: WhatsApp | L28: Wallet | M28: Tablet | N28: 6999 | O28: 40 | P28: 2799.6 | Q28: 4199.4 | R28: 755.89 | S28: 3443.51 | T28: 1688.9 | U28: 1754.61 | V28: 50.95 | W28: No | Y28: No | Z28: 1
A29: EDU02388 | B29: 27-06-2023 | C29: Embibe | D29: Professional Upskilling | E29: Data Analytics Bootcamp | F29: Gurugram | G29: Delhi NCR | H29: Tier 1 | I29: Other | J29: 35-44 | K29: Word of Mouth | L29: Net Banking | M29: Mobile | N29: 19999 | O29: 40 | P29: 7999.6 | Q29: 11999.4 | R29: 2159.89 | S29: 9839.51 | T29: 4786.15 | U29: 5053.36 | V29: 51.36 | W29: Yes | X29: 3.4 | Y29: No | Z29: 0
A30: EDU01927 | B30: 17-07-2024 | C30: Leverage Edu | D30: K-12 Academics | E30: Class 8-10 Science Pack | F30: Howrah | G30: West Bengal | H30: Tier 3 | I30: Male | J30: 18-24 | K30: School/College Partnership | L30: Net Banking | M30: Mobile | N30: 4999 | O30: 0 | P30: 0 | Q30: 4999 | R30: 899.82 | S30: 4099.18 | T30: 2251.19 | U30: 1847.99 | V30: 45.08 | W30: No | Y30: Yes | Z30: 2
A31: EDU00661 | B31: 10-04-2024 | C31: Great Learning | D31: Coding & Tech | E31: Data Science Masters | F31: Vadodara | G31: Gujarat | H31: Tier 3 | I31: Other | J31: 25-34 | K31: Instagram | L31: Net Banking | M31: Tablet | N31: 34999 | O31: 0 | P31: 0 | Q31: 34999 | R31: 6299.82 | S31: 28699.18 | T31: 15004.71 | U31: 13694.47 | V31: 47.72 | W31: Yes | X31: 4.2 | Y31: No | Z31: 0
A32: EDU01751 | B32: 27-06-2023 | C32: Extramarks | D32: Test Preparation | E32: SAT Complete Prep | F32: Faridabad | G32: Delhi NCR | H32: Tier 2 | I32: Other | J32: 25-34 | K32: Word of Mouth | L32: Debit Card | M32: Tablet | N32: 12999 | O32: 20 | P32: 2599.8 | Q32: 10399.2 | R32: 1871.86 | S32: 8527.34 | T32: 4283.93 | U32: 4243.41 | V32: 49.76 | W32: Yes | X32: 3.5 | Y32: No | Z32: 1
A33: EDU00116 | B33: 16-03-2024 | C33: Vedantu | D33: Creative Arts | E33: UI/UX Design | F33: Mumbai | G33: Maharashtra | H33: Tier 1 | I33: Other | J33: 25-34 | K33: Instagram | L33: Net Banking | M33: Tablet | N33: 14999 | O33: 50 | P33: 7499.5 | Q33: 7499.5 | R33: 1349.91 | S33: 6149.59 | T33: 3376.6 | U33: 2772.99 | V33: 45.09 | W33: Yes | X33: 3.7 | Y33: No | Z33: 0
A34: EDU01438 | B34: 02-06-2023 | C34: Scaler | D34: Professional Upskilling | E34: Financial Modelling | F34: Nashik | G34: Maharashtra | H34: Tier 2 | I34: Male | J34: 45+ | K34: WhatsApp | L34: Wallet | M34: Mobile | N34: 15999 | O34: 10 | P34: 1599.9 | Q34: 14399.1 | R34: 2591.84 | S34: 11807.26 | T34: 5560.38 | U34: 6246.88 | V34: 52.91 | W34: Yes | X34: 2.7 | Y34: No | Z34: 1
A35: EDU02469 | B35: 12-10-2023 | C35: Doubtnut | D35: Professional Upskilling | E35: HR Management | F35: Hyderabad | G35: Telangana | H35: Tier 1 | I35: Male | J35: 25-34 | K35: Instagram | L35: Credit Card | M35: Mobile | N35: 8999 | O35: 0 | P35: 0 | Q35: 8999 | R35: 1619.82 | S35: 7379.18 | T35: 2355.9 | U35: 5023.28 | V35: 68.07 | W35: No | Y35: Yes | Z35: 0
A36: EDU01030 | B36: 11-03-2024 | C36: Toppr | D36: K-12 Academics | E36: Class 11-12 PCB | F36: Chennai | G36: Tamil Nadu | H36: Tier 1 | I36: Male | J36: 25-34 | K36: Direct/Organic | L36: Net Banking | M36: Mobile | N36: 8499 | O36: 20 | P36: 1699.8 | Q36: 6799.2 | R36: 1223.86 | S36: 5575.34 | T36: 2362.25 | U36: 3213.09 | V36: 57.63 | W36: No | Y36: No | Z36: 1
A37: EDU00451 | B37: 20-07-2024 | C37: Scaler | D37: Higher Education | E37: B.Tech CSE Support | F37: Warangal | G37: Telangana | H37: Tier 3 | I37: Female | J37: 25-34 | K37: Word of Mouth | L37: Credit Card | M37: Desktop | N37: 9999 | O37: 0 | P37: 0 | Q37: 9999 | R37: 1799.82 | S37: 8199.18 | T37: 3293.48 | U37: 4905.7 | V37: 59.83 | W37: Yes | X37: 2.8 | Y37: No | Z37: 1
A38: EDU01690 | B38: 21-08-2024 | C38: Leverage Edu | D38: Professional Upskilling | E38: Digital Marketing Pro | F38: Faridabad | G38: Delhi NCR | H38: Tier 2 | I38: Other | J38: 13-17 | K38: WhatsApp | L38: Wallet | M38: Tablet | N38: 12999 | O38: 0 | P38: 0 | Q38: 12999 | R38: 2339.82 | S38: 10659.18 | T38: 5160.76 | U38: 5498.42 | V38: 51.58 | W38: No | Y38: No | Z38: 0
A39: EDU00493 | B39: 28-11-2023 | C39: BYJU'S | D39: Language Learning | E39: Business English | F39: New Delhi | G39: Delhi NCR | H39: Tier 1 | I39: Male | J39: 18-24 | K39: Word of Mouth | L39: Debit Card | M39: Desktop | N39: 6999 | O39: 15 | P39: 1049.85 | Q39: 5949.15 | R39: 1070.85 | S39: 4878.3 | T39: 2141.47 | U39: 2736.83 | V39: 56.1 | W39: No | Y39: No | Z39: 0
A40: EDU01138 | B40: 08-12-2023 | C40: Doubtnut | D40: Coding & Tech | E40: Data Science Masters | F40: Pune | G40: Maharashtra | H40: Tier 1 | I40: Male | J40: 35-44 | K40: WhatsApp | L40: Net Banking | M40: Desktop | N40: 34999 | O40: 30 | P40: 10499.7 | Q40: 24499.3 | R40: 4409.87 | S40: 20089.43 | T40: 5458.37 | U40: 14631.06 | V40: 72.83 | W40: No | Y40: Yes | Z40: 0
...

Sheet Working Data
A1: Enrollment_ID | B1: Enrollment_Date | C1: Company | D1: Course_Category | E1: Course_Name | F1: City | G1: State | H1: City_Tier | I1: Gender | J1: Age_Group | K1: Referral_Source | L1: Payment_Mode | M1: Device_Type | N1: Original_Price_INR | O1: Discount_% | P1: Discount_Amount_INR | Q1: Final_Price_INR | R1: GST_Amount_INR | S1: Net_Revenue_INR | T1: Platform_Cost_INR | U1: Gross_Profit_INR | V1: Gross_Margin_% | W1: Course_Completed | X1: Student_Rating | Y1: Refund_Issued | Z1: Support_Tickets_Raised | AA1: Cleaned_City | AB1: Cleaned_Company | AC1: Discount_Category | AD1: Profit_Flag | AE1: Month_Year | AF1: Year | AG1: Quarter
A2: EDU00524 | B2: 08-11-2023 | C2: Embibe | D2: Coding & Tech | E2: Python for Beginners | F2: Jodhpur | G2: Rajasthan | H2: Tier 3 | I2: Male | J2: 25-34 | K2: Google Ads | L2: Debit Card | M2: Desktop | N2: 7999 | O2: 40 | P2: 3199.6 | Q2: 4799.4 | R2: 863.89 | S2: 3935.51 | T2: 2203.97 | U2: 1731.54 | V2: 44 | W2: Yes | X2: 4.6 | Y2: No | Z2: 1 | AA2: =TRIM(PROPER(F2)) -> Jodhpur | AB2: =TRIM(PROPER(C2)) -> Embibe | AC2: =IF(O2=0,"No Discount",IF(O2<=15,"Low (1-15%)",IF(O2<=30,"Medium (16-30%)","High (>30%)"))) -> High (>30%) | AD2: =IF(V2<0,"Loss Making",IF(V2<20,"Low Margin","Healthy Margin")) -> Healthy Margin | AE2: =TEXT(DATE(VALUE(RIGHT(B2,4)),VALUE(MID(B2,4,2)),VALUE(LEFT(B2,2))),"MMM-YYYY") -> Nov-2023 | AF2: =VALUE(RIGHT(B2,4)) -> 2023 | AG2: =CHOOSE(ROUNDUP(VALUE(MID(B2,4,2))/3,0),"Q1","Q2","Q3","Q4") -> Q4
A3: EDU00061 | B3: 05-12-2023 | C3: Meritnation | D3: Test Preparation | E3: GRE Verbal+Quant | F3: Mangaluru | G3: Karnataka | H3: Tier 3 | I3: Male | J3: 25-34 | K3: Instagram | L3: Wallet | M3: Tablet | N3: 11999 | O3: 10 | P3: 1199.9 | Q3: 10799.1 | R3: 1943.84 | S3: 8855.26 | T3: 3836.62 | U3: 5018.64 | V3: 56.67 | W3: Yes | X3: 4 | Y3: No | Z3: 0 | AA3: =TRIM(PROPER(F3)) -> Mangaluru | AB3: =TRIM(PROPER(C3)) -> Meritnation | AC3: =IF(O3=0,"No Discount",IF(O3<=15,"Low (1-15%)",IF(O3<=30,"Medium (16-30%)","High (>30%)"))) -> Low (1-15%) | AD3: =IF(V3<0,"Loss Making",IF(V3<20,"Low Margin","Healthy Margin")) -> Healthy Margin | AE3: =TEXT(DATE(VALUE(RIGHT(B3,4)),VALUE(MID(B3,4,2)),VALUE(LEFT(B3,2))),"MMM-YYYY") -> Dec-2023 | AF3: =VALUE(RIGHT(B3,4)) -> 2023 | AG3: =CHOOSE(ROUNDUP(VALUE(MID(B3,4,2))/3,0),"Q1","Q2","Q3","Q4") -> Q4
A4: EDU00457 | B4: 15-12-2024 | C4: Embibe | D4: Higher Education | E4: MBA Finance Prep | F4: Ghaziabad | G4: Delhi NCR | H4: Tier 2 | I4: Other | J4: 18-24 | K4: Word of Mouth | L4: Credit Card | M4: Mobile | N4: 11999 | O4: 25 | P4: 2999.75 | Q4: 8999.25 | R4: 1619.87 | S4: 7379.38 | T4: 3191.83 | U4: 4187.55 | V4: 56.75 | W4: Yes | X4: 3.6 | Y4: No | Z4: 0 | AA4: =TRIM(PROPER(F4)) -> Ghaziabad | AB4: =TRIM(PROPER(C4)) -> Embibe | AC4: =IF(O4=0,"No Discount",IF(O4<=15,"Low (1-15%)",IF(O4<=30,"Medium (16-30%)","High (>30%)"))) -> Medium (16-30%) | AD4: =IF(V4<0,"Loss Making",IF(V4<20,"Low Margin","Healthy Margin")) -> Healthy Margin | AE4: =TEXT(DATE(VALUE(RIGHT(B4,4)),VALUE(MID(B4,4,2)),VALUE(LEFT(B4,2))),"MMM-YYYY") -> Dec-2024 | AF4: =VALUE(RIGHT(B4,4)) -> 2024 | AG4: =CHOOSE(ROUNDUP(VALUE(MID(B4,4,2))/3,0),"Q1","Q2","Q3","Q4") -> Q4
A5: EDU01052 | B5: 29-08-2024 | C5: Toppr | D5: Test Preparation | E5: SAT Complete Prep | F5: Ahmedabad | G5: Gujarat | H5: Tier 1 | I5: Male | J5: 13-17 | K5: YouTube | L5: Credit Card | M5: Mobile | N5: 12999 | O5: 0 | P5: 0 | Q5: 12999 | R5: 2339.82 | S5: 10659.18 | T5: 3738.71 | U5: 6920.47 | V5: 64.92 | W5: Yes | X5: 3.7 | Y5: No | Z5: 1 | AA5: =TRIM(PROPER(F5)) -> Ahmedabad | AB5: =TRIM(PROPER(C5)) -> Toppr | AC5: =IF(O5=0,"No Discount",IF(O5<=15,"Low (1-15%)",IF(O5<=30,"Medium (16-30%)","High (>30%)"))) -> No Discount | AD5: =IF(V5<0,"Loss Making",IF(V5<20,"Low Margin","Healthy Margin")) -> Healthy Margin | AE5: =TEXT(DATE(VALUE(RIGHT(B5,4)),VALUE(MID(B5,4,2)),VALUE(LEFT(B5,2))),"MMM-YYYY") -> Aug-2024 | AF5: =VALUE(RIGHT(B5,4)) -> 2024 | AG5: =CHOOSE(ROUNDUP(VALUE(MID(B5,4,2))/3,0),"Q1","Q2","Q3","Q4") -> Q3
A6: EDU00891 | B6: 09-02-2023 | C6: Vedantu | D6: Test Preparation | E6: SAT Complete Prep | F6: Kolkata | G6: West Bengal | H6: Tier 1 | I6: Other | J6: 35-44 | K6: Google Ads | L6: Debit Card | M6: Desktop | N6: 12999 | O6: 40 | P6: 5199.6 | Q6: 7799.4 | R6: 1403.89 | S6: 6395.51 | T6: 3376.69 | U6: 3018.82 | V6: 47.2 | W6: Yes | X6: 3.6 | Y6: No | Z6: 0 | AA6: =TRIM(PROPER(F6)) -> Kolkata | AB6: =TRIM(PROPER(C6)) -> Vedantu | AC6: =IF(O6=0,"No Discount",IF(O6<=15,"Low (1-15%)",IF(O6<=30,"Medium (16-30%)","High (>30%)"))) -> High (>30%) | AD6: =IF(V6<0,"Loss Making",IF(V6<20,"Low Margin","Healthy Margin")) -> Healthy Margin | AE6: =TEXT(DATE(VALUE(RIGHT(B6,4)),VALUE(MID(B6,4,2)),VALUE(LEFT(B6,2))),"MMM-YYYY") -> Feb-2023 | AF6: =VALUE(RIGHT(B6,4)) -> 2023 | AG6: =CHOOSE(ROUNDUP(VALUE(MID(B6,4,2))/3,0),"Q1","Q2","Q3","Q4") -> Q1
A7: EDU01966 | B7: 12-01-2023 | C7: Toppr | D7: Professional Upskilling | E7: Digital Marketing Pro | F7: Gurugram | G7: Delhi NCR | H7: Tier 1 | I7: Female | J7: 25-34 | K7: WhatsApp | L7: EMI | M7: Mobile | N7: 12999 | O7: 0 | P7: 0 | Q7: 12999 | R7: 2339.82 | S7: 10659.18 | T7: 3264.37 | U7: 7394.81 | V7: 69.38 | W7: Yes | X7: 4.5 | Y7: No | Z7: 1 | AA7: =TRIM(PROPER(F7)) -> Gurugram | AB7: =TRIM(PROPER(C7)) -> Toppr | AC7: =IF(O7=0,"No Discount",IF(O7<=15,"Low (1-15%)",IF(O7<=30,"Medium (16-30%)","High (>30%)"))) -> No Discount | AD7: =IF(V7<0,"Loss Making",IF(V7<20,"Low Margin","Healthy Margin")) -> Healthy Margin | AE7: =TEXT(DATE(VALUE(RIGHT(B7,4)),VALUE(MID(B7,4,2)),VALUE(LEFT(B7,2))),"MMM-YYYY") -> Jan-2023 | AF7: =VALUE(RIGHT(B7,4)) -> 2023 | AG7: =CHOOSE(ROUNDUP(VALUE(MID(B7,4,2))/3,0),"Q1","Q2","Q3","Q4") -> Q1
A8: EDU00027 | B8: 03-11-2023 | C8: BYJU'S | D8: Higher Education | E8: MBA Finance Prep | F8: Vadodara | G8: Gujarat | H8: Tier 3 | I8: Male | J8: 25-34 | K8: School/College Partnership | L8: EMI | M8: Mobile | N8: 11999 | O8: 0 | P8: 0 | Q8: 11999 | R8: 2159.82 | S8: 9839.18 | T8: 4348.29 | U8: 5490.89 | V8: 55.81 | W8: No | Y8: No | Z8: 1 | AA8: =TRIM(PROPER(F8)) -> Vadodara | AB8: =TRIM(PROPER(C8)) -> Byju'S | AC8: =IF(O8=0,"No Discount",IF(O8<=15,"Low (1-15%)",IF(O8<=30,"Medium (16-30%)","High (>30%)"))) -> No Discount | AD8: =IF(V8<0,"Loss Making",IF(V8<20,"Low Margin","Healthy Margin")) -> Healthy Margin | AE8: =TEXT(DATE(VALUE(RIGHT(B8,4)),VALUE(MID(B8,4,2)),VALUE(LEFT(B8,2))),"MMM-YYYY") -> Nov-2023 | AF8: =VALUE(RIGHT(B8,4)) -> 2023 | AG8: =CHOOSE(ROUNDUP(VALUE(MID(B8,4,2))/3,0),"Q1","Q2","Q3","Q4") -> Q4
A9: EDU00427 | B9: 18-01-2024 | C9: upGrad | D9: Creative Arts | E9: Video Editing Basics | F9: Pune | G9: Maharashtra | H9: Tier 1 | I9: Female | J9: 35-44 | K9: Word of Mouth | L9: Debit Card | M9: Mobile | N9: 6999 | O9: 5 | P9: 349.95 | Q9: 6649.05 | R9: 1196.83 | S9: 5452.22 | T9: 2206.78 | U9: 3245.44 | V9: 59.53 | W9: Yes | X9: 2.9 | Y9: No | Z9: 2 | AA9: =TRIM(PROPER(F9)) -> Pune | AB9: =TRIM(PROPER(C9)) -> Upgrad | AC9: =IF(O9=0,"No Discount",IF(O9<=15,"Low (1-15%)",IF(O9<=30,"Medium (16-30%)","High (>30%)"))) -> Low (1-15%) | AD9: =IF(V9<0,"Loss Making",IF(V9<20,"Low Margin","Healthy Margin")) -> Healthy Margin | AE9: =TEXT(DATE(VALUE(RIGHT(B9,4)),VALUE(MID(B9,4,2)),VALUE(LEFT(B9,2))),"MMM-YYYY") -> Jan-2024 | AF9: =VALUE(RIGHT(B9,4)) -> 2024 | AG9: =CHOOSE(ROUNDUP(VALUE(MID(B9,4,2))/3,0),"Q1","Q2","Q3","Q4") -> Q1
A10: EDU01634 | B10: 16-01-2023 | C10: Physics Wallah | D10: Creative Arts | E10: UI/UX Design | F10: Warangal | G10: Telangana | H10: Tier 3 | I10: Male | J10: 35-44 | K10: Direct/Organic | L10: EMI | M10: Mobile | N10: 14999 | O10: 25 | P10: 3749.75 | Q10: 11249.25 | R10: 2024.87 | S10: 9224.38 | T10: 4357.82 | U10: 4866.56 | V10: 52.76 | W10: No | Y10: No | Z10: 1 | AA10: =TRIM(PROPER(F10)) -> Warangal | AB10: =TRIM(PROPER(C10)) -> Physics Wallah | AC10: =IF(O10=0,"No Discount",IF(O10<=15,"Low (1-15%)",IF(O10<=30,"Medium (16-30%)","High (>30%)"))) -> Medium (16-30%) | AD10: =IF(V10<0,"Loss Making",IF(V10<20,"Low Margin","Healthy Margin")) -> Healthy Margin | AE10: =TEXT(DATE(VALUE(RIGHT(B10,4)),VALUE(MID(B10,4,2)),VALUE(LEFT(B10,2))),"MMM-YYYY") -> Jan-2023 | AF10: =VALUE(RIGHT(B10,4)) -> 2023 | AG10: =CHOOSE(ROUNDUP(VALUE(MID(B10,4,2))/3,0),"Q1","Q2","Q3","Q4") -> Q1
A11: EDU00833 | B11: 03-11-2024 | C11: Vedantu | D11: Higher Education | E11: MBA Finance Prep | F11: Madurai | G11: Tamil Nadu | H11: Tier 3 | I11: Other | J11: 18-24 | K11: Instagram | L11: Credit Card | M11: Desktop | N11: 11999 | O11: 50 | P11: 5999.5 | Q11: 5999.5 | R11: 1079.91 | S11: 4919.59 | T11: 2534.61 | U11: 2384.98 | V11: 48.48 | W11: No | Y11: No | Z11: 0 | AA11: =TRIM(PROPER(F11)) -> Madurai | AB11: =TRIM(PROPER(C11)) -> Vedantu | AC11: =IF(O11=0,"No Discount",IF(O11<=15,"Low (1-15%)",IF(O11<=30,"Medium (16-30%)","High (>30%)"))) -> High (>30%) | AD11: =IF(V11<0,"Loss Making",IF(V11<20,"Low Margin","Healthy Margin")) -> Healthy Margin | AE11: =TEXT(DATE(VALUE(RIGHT(B11,4)),VALUE(MID(B11,4,2)),VALUE(LEFT(B11,2))),"MMM-YYYY") -> Nov-2024 | AF11: =VALUE(RIGHT(B11,4)) -> 2024 | AG11: =CHOOSE(ROUNDUP(VALUE(MID(B11,4,2))/3,0),"Q1","Q2","Q3","Q4") -> Q4
A12: EDU02161 | B12: 15-11-2023 | C12: Toppr | D12: Test Preparation | E12: SAT Complete Prep | F12: NOIDA | G12: Delhi NCR | H12: Tier 1 | I12: Male | J12: 18-24 | K12: Email Campaign | L12: UPI | M12: Mobile | N12: 12999 | O12: 40 | P12: 5199.6 | Q12: 7799.4 | R12: 1403.89 | S12: 6395.51 | T12: 2933.31 | U12: 3462.2 | V12: 54.13 | W12: No | Y12: Yes | Z12: 1 | AA12: =TRIM(PROPER(F12)) -> Noida | AB12: =TRIM(PROPER(C12)) -> Toppr | AC12: =IF(O12=0,"No Discount",IF(O12<=15,"Low (1-15%)",IF(O12<=30,"Medium (16-30%)","High (>30%)"))) -> High (>30%) | AD12: =IF(V12<0,"Loss Making",IF(V12<20,"Low Margin","Healthy Margin")) -> Healthy Margin | AE12: =TEXT(DATE(VALUE(RIGHT(B12,4)),VALUE(MID(B12,4,2)),VALUE(LEFT(B12,2))),"MMM-YYYY") -> Nov-2023 | AF12: =VALUE(RIGHT(B12,4)) -> 2023 | AG12: =CHOOSE(ROUNDUP(VALUE(MID(B12,4,2))/3,0),"Q1","Q2","Q3","Q4") -> Q4
A13: EDU01493 | B13: 19-02-2024 | C13: Embibe | D13: Higher Education | E13: B.Tech CSE Support | F13: Warangal | G13: Telangana | H13: Tier 3 | I13: Male | J13: 13-17 | K13: YouTube | L13: Credit Card | M13: Mobile | N13: 9999 | O13: 10 | P13: 999.9 | Q13: 8999.1 | R13: 1619.84 | S13: 7379.26 | T13: 3528.47 | U13: 3850.79 | V13: 52.18 | W13: No | Y13: No | Z13: 1 | AA13: =TRIM(PROPER(F13)) -> Warangal | AB13: =TRIM(PROPER(C13)) -> Embibe | AC13: =IF(O13=0,"No Discount",IF(O13<=15,"Low (1-15%)",IF(O13<=30,"Medium (16-30%)","High (>30%)"))) -> Low (1-15%) | AD13: =IF(V13<0,"Loss Making",IF(V13<20,"Low Margin","Healthy Margin")) -> Healthy Margin | AE13: =TEXT(DATE(VALUE(RIGHT(B13,4)),VALUE(MID(B13,4,2)),VALUE(LEFT(B13,2))),"MMM-YYYY") -> Feb-2024 | AF13: =VALUE(RIGHT(B13,4)) -> 2024 | AG13: =CHOOSE(ROUNDUP(VALUE(MID(B13,4,2))/3,0),"Q1","Q2","Q3","Q4") -> Q1
A14: EDU02280 | B14: 14-10-2023 | C14: Simplilearn | D14: Professional Upskilling | E14: Digital Marketing Pro | F14: Mysuru | G14: Karnataka | H14: Tier 2 | I14: Female | J14: 25-34 | K14: WhatsApp | L14: EMI | M14: Desktop | N14: 12999 | O14: 20 | P14: 2599.8 | Q14: 10399.2 | R14: 1871.86 | S14: 8527.34 | T14: 3512.35 | U14: 5014.99 | V14: 58.81 | W14: No | Y14: No | Z14: 1 | AA14: =TRIM(PROPER(F14)) -> Mysuru | AB14: =TRIM(PROPER(C14)) -> Simplilearn | AC14: =IF(O14=0,"No Discount",IF(O14<=15,"Low (1-15%)",IF(O14<=30,"Medium (16-30%)","High (>30%)"))) -> Medium (16-30%) | AD14: =IF(V14<0,"Loss Making",IF(V14<20,"Low Margin","Healthy Margin")) -> Healthy Margin | AE14: =TEXT(DATE(VALUE(RIGHT(B14,4)),VALUE(MID(B14,4,2)),VALUE(LEFT(B14,2))),"MMM-YYYY") -> Oct-2023 | AF14: =VALUE(RIGHT(B14,4)) -> 2023 | AG14: =CHOOSE(ROUNDUP(VALUE(MID(B14,4,2))/3,0),"Q1","Q2","Q3","Q4") -> Q4
A15: EDU00700 | B15: 02-11-2023 | C15: BYJU'S | D15: Language Learning | E15: English Communication | F15: Chennai | G15: Tamil Nadu | H15: Tier 1 | I15: Male | J15: 13-17 | K15: Word of Mouth | L15: Credit Card | M15: Tablet | N15: 4999 | O15: 15 | P15: 749.85 | Q15: 4249.15 | R15: 764.85 | S15: 3484.3 | T15: 1347.82 | U15: 2136.48 | V15: 61.32 | W15: No | Y15: No | Z15: 3 | AA15: =TRIM(PROPER(F15)) -> Chennai | AB15: =TRIM(PROPER(C15)) -> Byju'S | AC15: =IF(O15=0,"No Discount",IF(O15<=15,"Low (1-15%)",IF(O15<=30,"Medium (16-30%)","High (>30%)"))) -> Low (1-15%) | AD15: =IF(V15<0,"Loss Making",IF(V15<20,"Low Margin","Healthy Margin")) -> Healthy Margin | AE15: =TEXT(DATE(VALUE(RIGHT(B15,4)),VALUE(MID(B15,4,2)),VALUE(LEFT(B15,2))),"MMM-YYYY") -> Nov-2023 | AF15: =VALUE(RIGHT(B15,4)) -> 2023 | AG15: =CHOOSE(ROUNDUP(VALUE(MID(B15,4,2))/3,0),"Q1","Q2","Q3","Q4") -> Q4
A16: EDU02121 | B16: 21-12-2024 | C16: Great Learning | D16: Coding & Tech | E16: Full Stack Development | F16: Bengaluru | G16: Karnataka | H16: Tier 1 | I16: Female | J16: 45+ | K16: Direct/Organic | L16: UPI | M16: Tablet | N16: 29999 | O16: 40 | P16: 11999.6 | Q16: 17999.4 | R16: 3239.89 | S16: 14759.51 | T16: 6414.9 | U16: 8344.61 | V16: 56.54 | W16: Yes | X16: 4.2 | Y16: No | Z16: 0 | AA16: =TRIM(PROPER(F16)) -> Bengaluru | AB16: =TRIM(PROPER(C16)) -> Great Learning | AC16: =IF(O16=0,"No Discount",IF(O16<=15,"Low (1-15%)",IF(O16<=30,"Medium (16-30%)","High (>30%)"))) -> High (>30%) | AD16: =IF(V16<0,"Loss Making",IF(V16<20,"Low Margin","Healthy Margin")) -> Healthy Margin | AE16: =TEXT(DATE(VALUE(RIGHT(B16,4)),VALUE(MID(B16,4,2)),VALUE(LEFT(B16,2))),"MMM-YYYY") -> Dec-2024 | AF16: =VALUE(RIGHT(B16,4)) -> 2024 | AG16: =CHOOSE(ROUNDUP(VALUE(MID(B16,4,2))/3,0),"Q1","Q2","Q3","Q4") -> Q4
A17: EDU00341 | B17: 10-11-2024 | C17: Doubtnut | D17: Creative Arts | E17: Graphic Design Pro | F17: Vadodara | G17: Gujarat | H17: Tier 3 | I17: Male | J17: 18-24 | K17: Direct/Organic | L17: Net Banking | M17: Mobile | N17: 9999 | O17: 25 | P17: 2499.75 | Q17: 7499.25 | R17: 1349.87 | S17: 6149.38 | T17: 2274.96 | U17: 3874.42 | V17: 63.01 | W17: No | Y17: No | Z17: 3 | AA17: =TRIM(PROPER(F17)) -> Vadodara | AB17: =TRIM(PROPER(C17)) -> Doubtnut | AC17: =IF(O17=0,"No Discount",IF(O17<=15,"Low (1-15%)",IF(O17<=30,"Medium (16-30%)","High (>30%)"))) -> Medium (16-30%) | AD17: =IF(V17<0,"Loss Making",IF(V17<20,"Low Margin","Healthy Margin")) -> Healthy Margin | AE17: =TEXT(DATE(VALUE(RIGHT(B17,4)),VALUE(MID(B17,4,2)),VALUE(LEFT(B17,2))),"MMM-YYYY") -> Nov-2024 | AF17: =VALUE(RIGHT(B17,4)) -> 2024 | AG17: =CHOOSE(ROUNDUP(VALUE(MID(B17,4,2))/3,0),"Q1","Q2","Q3","Q4") -> Q4
A18: EDU02148 | B18: 20-11-2023 | C18: Extramarks | D18: Test Preparation | E18: SAT Complete Prep | F18: Nashik | G18: Maharashtra | H18: Tier 2 | I18: Female | J18: 35-44 | K18: Email Campaign | L18: Wallet | M18: Desktop | N18: 12999 | O18: 40 | P18: 5199.6 | Q18: 7799.4 | R18: 1403.89 | S18: 6395.51 | T18: 3570.77 | U18: 2824.74 | V18: 44.17 | W18: No | Y18: No | Z18: 0 | AA18: =TRIM(PROPER(F18)) -> Nashik | AB18: =TRIM(PROPER(C18)) -> Extramarks | AC18: =IF(O18=0,"No Discount",IF(O18<=15,"Low (1-15%)",IF(O18<=30,"Medium (16-30%)","High (>30%)"))) -> High (>30%) | AD18: =IF(V18<0,"Loss Making",IF(V18<20,"Low Margin","Healthy Margin")) -> Healthy Margin | AE18: =TEXT(DATE(VALUE(RIGHT(B18,4)),VALUE(MID(B18,4,2)),VALUE(LEFT(B18,2))),"MMM-YYYY") -> Nov-2023 | AF18: =VALUE(RIGHT(B18,4)) -> 2023 | AG18: =CHOOSE(ROUNDUP(VALUE(MID(B18,4,2))/3,0),"Q1","Q2","Q3","Q4") -> Q4
A19: EDU00152 | B19: 24-11-2023 | C19: Simplilearn | D19: Competitive Exams | E19: GATE CS Complete | F19: Vadodara | G19: Gujarat | H19: Tier 3 | I19: Male | J19: 18-24 | K19: Email Campaign | L19: EMI | M19: Mobile | N19: 12999 | O19: 25 | P19: 3249.75 | Q19: 9749.25 | R19: 1754.87 | S19: 7994.38 | T19: 3501.87 | U19: 4492.51 | V19: 56.2 | W19: Yes | Y19: No | Z19: 0 | AA19: =TRIM(PROPER(F19)) -> Vadodara | AB19: =TRIM(PROPER(C19)) -> Simplilearn | AC19: =IF(O19=0,"No Discount",IF(O19<=15,"Low (1-15%)",IF(O19<=30,"Medium (16-30%)","High (>30%)"))) -> Medium (16-30%) | AD19: =IF(V19<0,"Loss Making",IF(V19<20,"Low Margin","Healthy Margin")) -> Healthy Margin | AE19: =TEXT(DATE(VALUE(RIGHT(B19,4)),VALUE(MID(B19,4,2)),VALUE(LEFT(B19,2))),"MMM-YYYY") -> Nov-2023 | AF19: =VALUE(RIGHT(B19,4)) -> 2023 | AG19: =CHOOSE(ROUNDUP(VALUE(MID(B19,4,2))/3,0),"Q1","Q2","Q3","Q4") -> Q4
A20: EDU01163 | B20: 15-06-2024 | C20: BYJU'S | D20: Language Learning | E20: Business English | F20: Nashik | G20: Maharashtra | H20: Tier 2 | I20: Male | J20: 18-24 | K20: Direct/Organic | L20: UPI | M20: Mobile | N20: 6999 | O20: 40 | P20: 2799.6 | Q20: 4199.4 | R20: 755.89 | S20: 3443.51 | T20: 1857.34 | U20: 1586.17 | V20: 46.06 | W20: Yes | X20: 4 | Y20: No | Z20: 0 | AA20: =TRIM(PROPER(F20)) -> Nashik | AB20: =TRIM(PROPER(C20)) -> Byju'S | AC20: =IF(O20=0,"No Discount",IF(O20<=15,"Low (1-15%)",IF(O20<=30,"Medium (16-30%)","High (>30%)"))) -> High (>30%) | AD20: =IF(V20<0,"Loss Making",IF(V20<20,"Low Margin","Healthy Margin")) -> Healthy Margin | AE20: =TEXT(DATE(VALUE(RIGHT(B20,4)),VALUE(MID(B20,4,2)),VALUE(LEFT(B20,2))),"MMM-YYYY") -> Jun-2024 | AF20: =VALUE(RIGHT(B20,4)) -> 2024 | AG20: =CHOOSE(ROUNDUP(VALUE(MID(B20,4,2))/3,0),"Q1","Q2","Q3","Q4") -> Q2
A21: EDU02226 | B21: 19-05-2023 | C21: BYJU'S | D21: Coding & Tech | E21: Python for Beginners | F21: Jaipur | G21: Rajasthan | H21: Tier 2 | I21: Male | J21: 18-24 | K21: Instagram | L21: Debit Card | M21: Mobile | N21: 7999 | O21: 0 | P21: 0 | Q21: 7999 | R21: 1439.82 | S21: 6559.18 | T21: 2831.55 | U21: 3727.63 | V21: 56.83 | W21: Yes | X21: 4.3 | Y21: No | Z21: 0 | AA21: =TRIM(PROPER(F21)) -> Jaipur | AB21: =TRIM(PROPER(C21)) -> Byju'S | AC21: =IF(O21=0,"No Discount",IF(O21<=15,"Low (1-15%)",IF(O21<=30,"Medium (16-30%)","High (>30%)"))) -> No Discount | AD21: =IF(V21<0,"Loss Making",IF(V21<20,"Low Margin","Healthy Margin")) -> Healthy Margin | AE21: =TEXT(DATE(VALUE(RIGHT(B21,4)),VALUE(MID(B21,4,2)),VALUE(LEFT(B21,2))),"MMM-YYYY") -> May-2023 | AF21: =VALUE(RIGHT(B21,4)) -> 2023 | AG21: =CHOOSE(ROUNDUP(VALUE(MID(B21,4,2))/3,0),"Q1","Q2","Q3","Q4") -> Q2
A22: EDU02334 | B22: 25-07-2024 | C22: BYJU'S | D22: Coding & Tech | E22: Full Stack Development | F22: Howrah | G22: West Bengal | H22: Tier 3 | I22: Female | J22: 25-34 | K22: Google Ads | L22: Wallet | M22: Mobile | N22: 29999 | O22: 40 | P22: 11999.6 | Q22: 17999.4 | R22: 3239.89 | S22: 14759.51 | T22: 7295.56 | U22: 7463.95 | V22: 50.57 | W22: Yes | Y22: No | Z22: 0 | AA22: =TRIM(PROPER(F22)) -> Howrah | AB22: =TRIM(PROPER(C22)) -> Byju'S | AC22: =IF(O22=0,"No Discount",IF(O22<=15,"Low (1-15%)",IF(O22<=30,"Medium (16-30%)","High (>30%)"))) -> High (>30%) | AD22: =IF(V22<0,"Loss Making",IF(V22<20,"Low Margin","Healthy Margin")) -> Healthy Margin | AE22: =TEXT(DATE(VALUE(RIGHT(B22,4)),VALUE(MID(B22,4,2)),VALUE(LEFT(B22,2))),"MMM-YYYY") -> Jul-2024 | AF22: =VALUE(RIGHT(B22,4)) -> 2024 | AG22: =CHOOSE(ROUNDUP(VALUE(MID(B22,4,2))/3,0),"Q1","Q2","Q3","Q4") -> Q3
A23: EDU00808 | B23: 09-10-2023 | C23: Doubtnut | D23: Test Preparation | E23: GRE Verbal+Quant | F23: Surat | G23: Gujarat | H23: Tier 2 | I23: Female | J23: 45+ | K23: Word of Mouth | L23: UPI | M23: Tablet | N23: 11999 | O23: 0 | P23: 0 | Q23: 11999 | R23: 2159.82 | S23: 9839.18 | T23: 4634.06 | U23: 5205.12 | V23: 52.9 | W23: Yes | X23: 3.1 | Y23: No | Z23: 2 | AA23: =TRIM(PROPER(F23)) -> Surat | AB23: =TRIM(PROPER(C23)) -> Doubtnut | AC23: =IF(O23=0,"No Discount",IF(O23<=15,"Low (1-15%)",IF(O23<=30,"Medium (16-30%)","High (>30%)"))) -> No Discount | AD23: =IF(V23<0,"Loss Making",IF(V23<20,"Low Margin","Healthy Margin")) -> Healthy Margin | AE23: =TEXT(DATE(VALUE(RIGHT(B23,4)),VALUE(MID(B23,4,2)),VALUE(LEFT(B23,2))),"MMM-YYYY") -> Oct-2023 | AF23: =VALUE(RIGHT(B23,4)) -> 2023 | AG23: =CHOOSE(ROUNDUP(VALUE(MID(B23,4,2))/3,0),"Q1","Q2","Q3","Q4") -> Q4
A24: EDU01261 | B24: 14-01-2024 | C24: Great Learning | D24: Competitive Exams | E24: IIT-JEE Advanced Prep | F24: Howrah | G24: West Bengal | H24: Tier 3 | I24: Female | J24: 18-24 | K24: Email Campaign | L24: Wallet | M24: Desktop | N24: 24999 | O24: 20 | P24: 4999.8 | Q24: 19999.2 | R24: 3599.86 | S24: 16399.34 | T24: 6763.99 | U24: 9635.35 | V24: 58.75 | W24: Yes | X24: 3.7 | Y24: No | Z24: 0 | AA24: =TRIM(PROPER(F24)) -> Howrah | AB24: =TRIM(PROPER(C24)) -> Great Learning | AC24: =IF(O24=0,"No Discount",IF(O24<=15,"Low (1-15%)",IF(O24<=30,"Medium (16-30%)","High (>30%)"))) -> Medium (16-30%) | AD24: =IF(V24<0,"Loss Making",IF(V24<20,"Low Margin","Healthy Margin")) -> Healthy Margin | AE24: =TEXT(DATE(VALUE(RIGHT(B24,4)),VALUE(MID(B24,4,2)),VALUE(LEFT(B24,2))),"MMM-YYYY") -> Jan-2024 | AF24: =VALUE(RIGHT(B24,4)) -> 2024 | AG24: =CHOOSE(ROUNDUP(VALUE(MID(B24,4,2))/3,0),"Q1","Q2","Q3","Q4") -> Q1
A25: EDU01083 | B25: 17-06-2023 | C25: Doubtnut | D25: Competitive Exams | E25: CAT Prep Masterclass | F25: Chennai | G25: Tamil Nadu | H25: Tier 1 | I25: Other | J25: 35-44 | K25: Google Ads | L25: Credit Card | M25: Desktop | N25: 14999 | O25: 0 | P25: 0 | Q25: 14999 | R25: 2699.82 | S25: 12299.18 | T25: 4245.97 | U25: 8053.21 | V25: 65.48 | W25: Yes | X25: 3.4 | Y25: No | Z25: 0 | AA25: =TRIM(PROPER(F25)) -> Chennai | AB25: =TRIM(PROPER(C25)) -> Doubtnut | AC25: =IF(O25=0,"No Discount",IF(O25<=15,"Low (1-15%)",IF(O25<=30,"Medium (16-30%)","High (>30%)"))) -> No Discount | AD25: =IF(V25<0,"Loss Making",IF(V25<20,"Low Margin","Healthy Margin")) -> Healthy Margin | AE25: =TEXT(DATE(VALUE(RIGHT(B25,4)),VALUE(MID(B25,4,2)),VALUE(LEFT(B25,2))),"MMM-YYYY") -> Jun-2023 | AF25: =VALUE(RIGHT(B25,4)) -> 2023 | AG25: =CHOOSE(ROUNDUP(VALUE(MID(B25,4,2))/3,0),"Q1","Q2","Q3","Q4") -> Q2
A26: EDU00326 | B26: 05-01-2023 | C26: Meritnation | D26: Professional Upskilling | E26: Digital Marketing Pro | F26: Surat | G26: Gujarat | H26: Tier 2 | I26: Male | J26: 35-44 | K26: School/College Partnership | L26: Credit Card | M26: Mobile | N26: 12999 | O26: 50 | P26: 6499.5 | Q26: 6499.5 | R26: 1169.91 | S26: 5329.59 | T26: 2783.75 | U26: 2545.84 | V26: 47.77 | W26: No | Y26: No | Z26: 1 | AA26: =TRIM(PROPER(F26)) -> Surat | AB26: =TRIM(PROPER(C26)) -> Meritnation | AC26: =IF(O26=0,"No Discount",IF(O26<=15,"Low (1-15%)",IF(O26<=30,"Medium (16-30%)","High (>30%)"))) -> High (>30%) | AD26: =IF(V26<0,"Loss Making",IF(V26<20,"Low Margin","Healthy Margin")) -> Healthy Margin | AE26: =TEXT(DATE(VALUE(RIGHT(B26,4)),VALUE(MID(B26,4,2)),VALUE(LEFT(B26,2))),"MMM-YYYY") -> Jan-2023 | AF26: =VALUE(RIGHT(B26,4)) -> 2023 | AG26: =CHOOSE(ROUNDUP(VALUE(MID(B26,4,2))/3,0),"Q1","Q2","Q3","Q4") -> Q1
A27: EDU00465 | B27: 27-05-2024 | C27: Scaler | D27: K-12 Academics | E27: Class 8-10 Science Pack | F27: Madurai | G27: Tamil Nadu | H27: Tier 3 | I27: Female | J27: 35-44 | K27: YouTube | L27: UPI | M27: Desktop | N27: 4999 | O27: 5 | P27: 249.95 | Q27: 4749.05 | R27: 854.83 | S27: 3894.22 | T27: 2019.87 | U27: 1874.35 | V27: 48.13 | W27: No | Y27: No | Z27: 1 | AA27: =TRIM(PROPER(F27)) -> Madurai | AB27: =TRIM(PROPER(C27)) -> Scaler | AC27: =IF(O27=0,"No Discount",IF(O27<=15,"Low (1-15%)",IF(O27<=30,"Medium (16-30%)","High (>30%)"))) -> Low (1-15%) | AD27: =IF(V27<0,"Loss Making",IF(V27<20,"Low Margin","Healthy Margin")) -> Healthy Margin | AE27: =TEXT(DATE(VALUE(RIGHT(B27,4)),VALUE(MID(B27,4,2)),VALUE(LEFT(B27,2))),"MMM-YYYY") -> May-2024 | AF27: =VALUE(RIGHT(B27,4)) -> 2024 | AG27: =CHOOSE(ROUNDUP(VALUE(MID(B27,4,2))/3,0),"Q1","Q2","Q3","Q4") -> Q2
A28: EDU00745 | B28: 12-05-2023 | C28: Meritnation | D28: K-12 Academics | E28: Foundation Course | F28: Bengaluru | G28: Karnataka | H28: Tier 1 | I28: Female | J28: 35-44 | K28: WhatsApp | L28: Wallet | M28: Tablet | N28: 6999 | O28: 40 | P28: 2799.6 | Q28: 4199.4 | R28: 755.89 | S28: 3443.51 | T28: 1688.9 | U28: 1754.61 | V28: 50.95 | W28: No | Y28: No | Z28: 1 | AA28: =TRIM(PROPER(F28)) -> Bengaluru | AB28: =TRIM(PROPER(C28)) -> Meritnation | AC28: =IF(O28=0,"No Discount",IF(O28<=15,"Low (1-15%)",IF(O28<=30,"Medium (16-30%)","High (>30%)"))) -> High (>30%) | AD28: =IF(V28<0,"Loss Making",IF(V28<20,"Low Margin","Healthy Margin")) -> Healthy Margin | AE28: =TEXT(DATE(VALUE(RIGHT(B28,4)),VALUE(MID(B28,4,2)),VALUE(LEFT(B28,2))),"MMM-YYYY") -> May-2023 | AF28: =VALUE(RIGHT(B28,4)) -> 2023 | AG28: =CHOOSE(ROUNDUP(VALUE(MID(B28,4,2))/3,0),"Q1","Q2","Q3","Q4") -> Q2
A29: EDU02388 | B29: 27-06-2023 | C29: Embibe | D29: Professional Upskilling | E29: Data Analytics Bootcamp | F29: Gurugram | G29: Delhi NCR | H29: Tier 1 | I29: Other | J29: 35-44 | K29: Word of Mouth | L29: Net Banking | M29: Mobile | N29: 19999 | O29: 40 | P29: 7999.6 | Q29: 11999.4 | R29: 2159.89 | S29: 9839.51 | T29: 4786.15 | U29: 5053.36 | V29: 51.36 | W29: Yes | X29: 3.4 | Y29: No | Z29: 0 | AA29: =TRIM(PROPER(F29)) -> Gurugram | AB29: =TRIM(PROPER(C29)) -> Embibe | AC29: =IF(O29=0,"No Discount",IF(O29<=15,"Low (1-15%)",IF(O29<=30,"Medium (16-30%)","High (>30%)"))) -> High (>30%) | AD29: =IF(V29<0,"Loss Making",IF(V29<20,"Low Margin","Healthy Margin")) -> Healthy Margin | AE29: =TEXT(DATE(VALUE(RIGHT(B29,4)),VALUE(MID(B29,4,2)),VALUE(LEFT(B29,2))),"MMM-YYYY") -> Jun-2023 | AF29: =VALUE(RIGHT(B29,4)) -> 2023 | AG29: =CHOOSE(ROUNDUP(VALUE(MID(B29,4,2))/3,0),"Q1","Q2","Q3","Q4") -> Q2
A30: EDU01927 | B30: 17-07-2024 | C30: Leverage Edu | D30: K-12 Academics | E30: Class 8-10 Science Pack | F30: Howrah | G30: West Bengal | H30: Tier 3 | I30: Male | J30: 18-24 | K30: School/College Partnership | L30: Net Banking | M30: Mobile | N30: 4999 | O30: 0 | P30: 0 | Q30: 4999 | R30: 899.82 | S30: 4099.18 | T30: 2251.19 | U30: 1847.99 | V30: 45.08 | W30: No | Y30: Yes | Z30: 2 | AA30: =TRIM(PROPER(F30)) -> Howrah | AB30: =TRIM(PROPER(C30)) -> Leverage Edu | AC30: =IF(O30=0,"No Discount",IF(O30<=15,"Low (1-15%)",IF(O30<=30,"Medium (16-30%)","High (>30%)"))) -> No Discount | AD30: =IF(V30<0,"Loss Making",IF(V30<20,"Low Margin","Healthy Margin")) -> Healthy Margin | AE30: =TEXT(DATE(VALUE(RIGHT(B30,4)),VALUE(MID(B30,4,2)),VALUE(LEFT(B30,2))),"MMM-YYYY") -> Jul-2024 | AF30: =VALUE(RIGHT(B30,4)) -> 2024 | AG30: =CHOOSE(ROUNDUP(VALUE(MID(B30,4,2))/3,0),"Q1","Q2","Q3","Q4") -> Q3
A31: EDU00661 | B31: 10-04-2024 | C31: Great Learning | D31: Coding & Tech | E31: Data Science Masters | F31: Vadodara | G31: Gujarat | H31: Tier 3 | I31: Other | J31: 25-34 | K31: Instagram | L31: Net Banking | M31: Tablet | N31: 34999 | O31: 0 | P31: 0 | Q31: 34999 | R31: 6299.82 | S31: 28699.18 | T31: 15004.71 | U31: 13694.47 | V31: 47.72 | W31: Yes | X31: 4.2 | Y31: No | Z31: 0 | AA31: =TRIM(PROPER(F31)) -> Vadodara | AB31: =TRIM(PROPER(C31)) -> Great Learning | AC31: =IF(O31=0,"No Discount",IF(O31<=15,"Low (1-15%)",IF(O31<=30,"Medium (16-30%)","High (>30%)"))) -> No Discount | AD31: =IF(V31<0,"Loss Making",IF(V31<20,"Low Margin","Healthy Margin")) -> Healthy Margin | AE31: =TEXT(DATE(VALUE(RIGHT(B31,4)),VALUE(MID(B31,4,2)),VALUE(LEFT(B31,2))),"MMM-YYYY") -> Apr-2024 | AF31: =VALUE(RIGHT(B31,4)) -> 2024 | AG31: =CHOOSE(ROUNDUP(VALUE(MID(B31,4,2))/3,0),"Q1","Q2","Q3","Q4") -> Q2
A32: EDU01751 | B32: 27-06-2023 | C32: Extramarks | D32: Test Preparation | E32: SAT Complete Prep | F32: Faridabad | G32: Delhi NCR | H32: Tier 2 | I32: Other | J32: 25-34 | K32: Word of Mouth | L32: Debit Card | M32: Tablet | N32: 12999 | O32: 20 | P32: 2599.8 | Q32: 10399.2 | R32: 1871.86 | S32: 8527.34 | T32: 4283.93 | U32: 4243.41 | V32: 49.76 | W32: Yes | X32: 3.5 | Y32: No | Z32: 1 | AA32: =TRIM(PROPER(F32)) -> Faridabad | AB32: =TRIM(PROPER(C32)) -> Extramarks | AC32: =IF(O32=0,"No Discount",IF(O32<=15,"Low (1-15%)",IF(O32<=30,"Medium (16-30%)","High (>30%)"))) -> Medium (16-30%) | AD32: =IF(V32<0,"Loss Making",IF(V32<20,"Low Margin","Healthy Margin")) -> Healthy Margin | AE32: =TEXT(DATE(VALUE(RIGHT(B32,4)),VALUE(MID(B32,4,2)),VALUE(LEFT(B32,2))),"MMM-YYYY") -> Jun-2023 | AF32: =VALUE(RIGHT(B32,4)) -> 2023 | AG32: =CHOOSE(ROUNDUP(VALUE(MID(B32,4,2))/3,0),"Q1","Q2","Q3","Q4") -> Q2
A33: EDU00116 | B33: 16-03-2024 | C33: Vedantu | D33: Creative Arts | E33: UI/UX Design | F33: Mumbai | G33: Maharashtra | H33: Tier 1 | I33: Other | J33: 25-34 | K33: Instagram | L33: Net Banking | M33: Tablet | N33: 14999 | O33: 50 | P33: 7499.5 | Q33: 7499.5 | R33: 1349.91 | S33: 6149.59 | T33: 3376.6 | U33: 2772.99 | V33: 45.09 | W33: Yes | X33: 3.7 | Y33: No | Z33: 0 | AA33: =TRIM(PROPER(F33)) -> Mumbai | AB33: =TRIM(PROPER(C33)) -> Vedantu | AC33: =IF(O33=0,"No Discount",IF(O33<=15,"Low (1-15%)",IF(O33<=30,"Medium (16-30%)","High (>30%)"))) -> High (>30%) | AD33: =IF(V33<0,"Loss Making",IF(V33<20,"Low Margin","Healthy Margin")) -> Healthy Margin | AE33: =TEXT(DATE(VALUE(RIGHT(B33,4)),VALUE(MID(B33,4,2)),VALUE(LEFT(B33,2))),"MMM-YYYY") -> Mar-2024 | AF33: =VALUE(RIGHT(B33,4)) -> 2024 | AG33: =CHOOSE(ROUNDUP(VALUE(MID(B33,4,2))/3,0),"Q1","Q2","Q3","Q4") -> Q1
A34: EDU01438 | B34: 02-06-2023 | C34: Scaler | D34: Professional Upskilling | E34: Financial Modelling | F34: Nashik | G34: Maharashtra | H34: Tier 2 | I34: Male | J34: 45+ | K34: WhatsApp | L34: Wallet | M34: Mobile | N34: 15999 | O34: 10 | P34: 1599.9 | Q34: 14399.1 | R34: 2591.84 | S34: 11807.26 | T34: 5560.38 | U34: 6246.88 | V34: 52.91 | W34: Yes | X34: 2.7 | Y34: No | Z34: 1 | AA34: =TRIM(PROPER(F34)) -> Nashik | AB34: =TRIM(PROPER(C34)) -> Scaler | AC34: =IF(O34=0,"No Discount",IF(O34<=15,"Low (1-15%)",IF(O34<=30,"Medium (16-30%)","High (>30%)"))) -> Low (1-15%) | AD34: =IF(V34<0,"Loss Making",IF(V34<20,"Low Margin","Healthy Margin")) -> Healthy Margin | AE34: =TEXT(DATE(VALUE(RIGHT(B34,4)),VALUE(MID(B34,4,2)),VALUE(LEFT(B34,2))),"MMM-YYYY") -> Jun-2023 | AF34: =VALUE(RIGHT(B34,4)) -> 2023 | AG34: =CHOOSE(ROUNDUP(VALUE(MID(B34,4,2))/3,0),"Q1","Q2","Q3","Q4") -> Q2
A35: EDU02469 | B35: 12-10-2023 | C35: Doubtnut | D35: Professional Upskilling | E35: HR Management | F35: Hyderabad | G35: Telangana | H35: Tier 1 | I35: Male | J35: 25-34 | K35: Instagram | L35: Credit Card | M35: Mobile | N35: 8999 | O35: 0 | P35: 0 | Q35: 8999 | R35: 1619.82 | S35: 7379.18 | T35: 2355.9 | U35: 5023.28 | V35: 68.07 | W35: No | Y35: Yes | Z35: 0 | AA35: =TRIM(PROPER(F35)) -> Hyderabad | AB35: =TRIM(PROPER(C35)) -> Doubtnut | AC35: =IF(O35=0,"No Discount",IF(O35<=15,"Low (1-15%)",IF(O35<=30,"Medium (16-30%)","High (>30%)"))) -> No Discount | AD35: =IF(V35<0,"Loss Making",IF(V35<20,"Low Margin","Healthy Margin")) -> Healthy Margin | AE35: =TEXT(DATE(VALUE(RIGHT(B35,4)),VALUE(MID(B35,4,2)),VALUE(LEFT(B35,2))),"MMM-YYYY") -> Oct-2023 | AF35: =VALUE(RIGHT(B35,4)) -> 2023 | AG35: =CHOOSE(ROUNDUP(VALUE(MID(B35,4,2))/3,0),"Q1","Q2","Q3","Q4") -> Q4
A36: EDU01030 | B36: 11-03-2024 | C36: Toppr | D36: K-12 Academics | E36: Class 11-12 PCB | F36: Chennai | G36: Tamil Nadu | H36: Tier 1 | I36: Male | J36: 25-34 | K36: Direct/Organic | L36: Net Banking | M36: Mobile | N36: 8499 | O36: 20 | P36: 1699.8 | Q36: 6799.2 | R36: 1223.86 | S36: 5575.34 | T36: 2362.25 | U36: 3213.09 | V36: 57.63 | W36: No | Y36: No | Z36: 1 | AA36: =TRIM(PROPER(F36)) -> Chennai | AB36: =TRIM(PROPER(C36)) -> Toppr | AC36: =IF(O36=0,"No Discount",IF(O36<=15,"Low (1-15%)",IF(O36<=30,"Medium (16-30%)","High (>30%)"))) -> Medium (16-30%) | AD36: =IF(V36<0,"Loss Making",IF(V36<20,"Low Margin","Healthy Margin")) -> Healthy Margin | AE36: =TEXT(DATE(VALUE(RIGHT(B36,4)),VALUE(MID(B36,4,2)),VALUE(LEFT(B36,2))),"MMM-YYYY") -> Mar-2024 | AF36: =VALUE(RIGHT(B36,4)) -> 2024 | AG36: =CHOOSE(ROUNDUP(VALUE(MID(B36,4,2))/3,0),"Q1","Q2","Q3","Q4") -> Q1
A37: EDU00451 | B37: 20-07-2024 | C37: Scaler | D37: Higher Education | E37: B.Tech CSE Support | F37: Warangal | G37: Telangana | H37: Tier 3 | I37: Female | J37: 25-34 | K37: Word of Mouth | L37: Credit Card | M37: Desktop | N37: 9999 | O37: 0 | P37: 0 | Q37: 9999 | R37: 1799.82 | S37: 8199.18 | T37: 3293.48 | U37: 4905.7 | V37: 59.83 | W37: Yes | X37: 2.8 | Y37: No | Z37: 1 | AA37: =TRIM(PROPER(F37)) -> Warangal | AB37: =TRIM(PROPER(C37)) -> Scaler | AC37: =IF(O37=0,"No Discount",IF(O37<=15,"Low (1-15%)",IF(O37<=30,"Medium (16-30%)","High (>30%)"))) -> No Discount | AD37: =IF(V37<0,"Loss Making",IF(V37<20,"Low Margin","Healthy Margin")) -> Healthy Margin | AE37: =TEXT(DATE(VALUE(RIGHT(B37,4)),VALUE(MID(B37,4,2)),VALUE(LEFT(B37,2))),"MMM-YYYY") -> Jul-2024 | AF37: =VALUE(RIGHT(B37,4)) -> 2024 | AG37: =CHOOSE(ROUNDUP(VALUE(MID(B37,4,2))/3,0),"Q1","Q2","Q3","Q4") -> Q3
A38: EDU01690 | B38: 21-08-2024 | C38: Leverage Edu | D38: Professional Upskilling | E38: Digital Marketing Pro | F38: Faridabad | G38: Delhi NCR | H38: Tier 2 | I38: Other | J38: 13-17 | K38: WhatsApp | L38: Wallet | M38: Tablet | N38: 12999 | O38: 0 | P38: 0 | Q38: 12999 | R38: 2339.82 | S38: 10659.18 | T38: 5160.76 | U38: 5498.42 | V38: 51.58 | W38: No | Y38: No | Z38: 0 | AA38: =TRIM(PROPER(F38)) -> Faridabad | AB38: =TRIM(PROPER(C38)) -> Leverage Edu | AC38: =IF(O38=0,"No Discount",IF(O38<=15,"Low (1-15%)",IF(O38<=30,"Medium (16-30%)","High (>30%)"))) -> No Discount | AD38: =IF(V38<0,"Loss Making",IF(V38<20,"Low Margin","Healthy Margin")) -> Healthy Margin | AE38: =TEXT(DATE(VALUE(RIGHT(B38,4)),VALUE(MID(B38,4,2)),VALUE(LEFT(B38,2))),"MMM-YYYY") -> Aug-2024 | AF38: =VALUE(RIGHT(B38,4)) -> 2024 | AG38: =CHOOSE(ROUNDUP(VALUE(MID(B38,4,2))/3,0),"Q1","Q2","Q3","Q4") -> Q3
A39: EDU00493 | B39: 28-11-2023 | C39: BYJU'S | D39: Language Learning | E39: Business English | F39: New Delhi | G39: Delhi NCR | H39: Tier 1 | I39: Male | J39: 18-24 | K39: Word of Mouth | L39: Debit Card | M39: Desktop | N39: 6999 | O39: 15 | P39: 1049.85 | Q39: 5949.15 | R39: 1070.85 | S39: 4878.3 | T39: 2141.47 | U39: 2736.83 | V39: 56.1 | W39: No | Y39: No | Z39: 0 | AA39: =TRIM(PROPER(F39)) -> New Delhi | AB39: =TRIM(PROPER(C39)) -> Byju'S | AC39: =IF(O39=0,"No Discount",IF(O39<=15,"Low (1-15%)",IF(O39<=30,"Medium (16-30%)","High (>30%)"))) -> Low (1-15%) | AD39: =IF(V39<0,"Loss Making",IF(V39<20,"Low Margin","Healthy Margin")) -> Healthy Margin | AE39: =TEXT(DATE(VALUE(RIGHT(B39,4)),VALUE(MID(B39,4,2)),VALUE(LEFT(B39,2))),"MMM-YYYY") -> Nov-2023 | AF39: =VALUE(RIGHT(B39,4)) -> 2023 | AG39: =CHOOSE(ROUNDUP(VALUE(MID(B39,4,2))/3,0),"Q1","Q2","Q3","Q4") -> Q4
A40: EDU01138 | B40: 08-12-2023 | C40: Doubtnut | D40: Coding & Tech | E40: Data Science Masters | F40: Pune | G40: Maharashtra | H40: Tier 1 | I40: Male | J40: 35-44 | K40: WhatsApp | L40: Net Banking | M40: Desktop | N40: 34999 | O40: 30 | P40: 10499.7 | Q40: 24499.3 | R40: 4409.87 | S40: 20089.43 | T40: 5458.37 | U40: 14631.06 | V40: 72.83 | W40: No | Y40: Yes | Z40: 0 | AA40: =TRIM(PROPER(F40)) -> Pune | AB40: =TRIM(PROPER(C40)) -> Doubtnut | AC40: =IF(O40=0,"No Discount",IF(O40<=15,"Low (1-15%)",IF(O40<=30,"Medium (16-30%)","High (>30%)"))) -> Medium (16-30%) | AD40: =IF(V40<0,"Loss Making",IF(V40<20,"Low Margin","Healthy Margin")) -> Healthy Margin | AE40: =TEXT(DATE(VALUE(RIGHT(B40,4)),VALUE(MID(B40,4,2)),VALUE(LEFT(B40,2))),"MMM-YYYY") -> Dec-2023 | AF40: =VALUE(RIGHT(B40,4)) -> 2023 | AG40: =CHOOSE(ROUNDUP(VALUE(MID(B40,4,2))/3,0),"Q1","Q2","Q3","Q4") -> Q4
...

Sheet Lookup Tables
A1: TABLE A: City → Tier & Regional Head Mapping | F1: TABLE B: GST Rate Reference
A2: City | B2: State | C2: City_Tier | D2: Regional_Head | F2: Price_Bracket | G2: GST_Rate_%
A3: New Delhi | B3: Delhi NCR | C3: Tier 1 | D3: Priya Sharma | F3: Below ₹1,000 | G3: 12%
A4: Gurugram | B4: Delhi NCR | C4: Tier 1 | D4: Priya Sharma | F4: ₹1,000 – ₹9,999 | G4: 18%
A5: Noida | B5: Delhi NCR | C5: Tier 1 | D5: Priya Sharma | F5: Above ₹10,000 | G5: 18%
A6: Faridabad | B6: Delhi NCR | C6: Tier 2 | D6: Arjun Mehta
A7: Ghaziabad | B7: Delhi NCR | C7: Tier 2 | D7: Arjun Mehta
A8: Mumbai | B8: Maharashtra | C8: Tier 1 | D8: Priya Sharma
A9: Pune | B9: Maharashtra | C9: Tier 1 | D9: Priya Sharma
A10: Nagpur | B10: Maharashtra | C10: Tier 2 | D10: Arjun Mehta
A11: Nashik | B11: Maharashtra | C11: Tier 2 | D11: Arjun Mehta
A12: Bengaluru | B12: Karnataka | C12: Tier 1 | D12: Priya Sharma
A13: Mysuru | B13: Karnataka | C13: Tier 2 | D13: Arjun Mehta
A14: Mangaluru | B14: Karnataka | C14: Tier 3 | D14: Kavita Iyer
A15: Chennai | B15: Tamil Nadu | C15: Tier 1 | D15: Priya Sharma
A16: Coimbatore | B16: Tamil Nadu | C16: Tier 2 | D16: Arjun Mehta
A17: Madurai | B17: Tamil Nadu | C17: Tier 3 | D17: Kavita Iyer
... A26: Jodhpur | B26: Rajasthan | C26: Tier 3 | D26: Kavita Iyer

Sheet KPI Summary
A1: EdTech India — KPI Summary (Formula-Based)
A3: SECTION 1: Performance by Course Category
A5: Course_Category | B5: Total_Enrollments | C5: Total_Net_Revenue_INR | D5: Total_Gross_Profit_INR | E5: Avg_Margin_% | F5: Completion_Rate_% | G5: Refund_Rate_% | H5: Avg_Rating
A6: K-12 Academics | B6: =COUNTIFS('Working Data'!D:D,A6) -> 311 | C6: =SUMIFS('Working Data'!S:S,'Working Data'!D:D,A6) -> 1535835.2 | D6: =SUMIFS('Working Data'!U:U,'Working Data'!D:D,A6) -> 861549.18 | E6: =IFERROR(D6/C6,0) -> 0.56096459 | F6: =IFERROR(COUNTIFS('Working Data'!D:D,A6,'Working Data'!W:W,"Yes")/B6,0) -> 0.60128617 | G6: =IFERROR(COUNTIFS('Working Data'!D:D,A6,'Working Data'!Y:Y,"Yes")/B6,0) -> 0.10610932 | H6: =IFERROR(AVERAGEIFS('Working Data'!X:X,'Working Data'!D:D,A6,'Working Data'!X:X,"<>"),"") -> 3.6691824
A7: Competitive Exams | B7: =COUNTIFS('Working Data'!D:D,A7) -> 322 | C7: =SUMIFS('Working Data'!S:S,'Working Data'!D:D,A7) -> 4154596.2 | D7: =SUMIFS('Working Data'!U:U,'Working Data'!D:D,A7) -> 2342879.5 | E7: =IFERROR(D7/C7,0) -> 0.56392471 | F7: =IFERROR(COUNTIFS('Working Data'!D:D,A7,'Working Data'!W:W,"Yes")/B7,0) -> 0.59006211 | G7: =IFERROR(COUNTIFS('Working Data'!D:D,A7,'Working Data'!Y:Y,"Yes")/B7,0) -> 0.080745342 | H7: =IFERROR(AVERAGEIFS('Working Data'!X:X,'Working Data'!D:D,A7,'Working Data'!X:X,"<>"),"") -> 3.6779874
A8: Higher Education | B8: =COUNTIFS('Working Data'!D:D,A8) -> 328 | C8: =SUMIFS('Working Data'!S:S,'Working Data'!D:D,A8) -> 2200349.6 | D8: =SUMIFS('Working Data'!U:U,'Working Data'!D:D,A8) -> 1230576.1 | E8: =IFERROR(D8/C8,0) -> 0.55926388 | F8: =IFERROR(COUNTIFS('Working Data'!D:D,A8,'Working Data'!W:W,"Yes")/B8,0) -> 0.59146341 | G8: =IFERROR(COUNTIFS('Working Data'!D:D,A8,'Working Data'!Y:Y,"Yes")/B8,0) -> 0.10060976 | H8: =IFERROR(AVERAGEIFS('Working Data'!X:X,'Working Data'!D:D,A8,'Working Data'!X:X,"<>"),"") -> 3.7288344
A9: Professional Upskilling | B9: =COUNTIFS('Working Data'!D:D,A9) -> 320 | C9: =SUMIFS('Working Data'!S:S,'Working Data'!D:D,A9) -> 3179253.1 | D9: =SUMIFS('Working Data'!U:U,'Working Data'!D:D,A9) -> 1794086.7 | E9: =IFERROR(D9/C9,0) -> 0.56431077 | F9: =IFERROR(COUNTIFS('Working Data'!D:D,A9,'Working Data'!W:W,"Yes")/B9,0) -> 0.63125 | G9: =IFERROR(COUNTIFS('Working Data'!D:D,A9,'Working Data'!Y:Y,"Yes")/B9,0) -> 0.075 | H9: =IFERROR(AVERAGEIFS('Working Data'!X:X,'Working Data'!D:D,A9,'Working Data'!X:X,"<>"),"") -> 3.9949153
A10: Coding & Tech | B10: =COUNTIFS('Working Data'!D:D,A10) -> 303 | C10: =SUMIFS('Working Data'!S:S,'Working Data'!D:D,A10) -> 5012087.2 | D10: =SUMIFS('Working Data'!U:U,'Working Data'!D:D,A10) -> 2949812.9 | E10: =IFERROR(D10/C10,0) -> 0.58853982 | F10: =IFERROR(COUNTIFS('Working Data'!D:D,A10,'Working Data'!W:W,"Yes")/B10,0) -> 0.66336634 | G10: =IFERROR(COUNTIFS('Working Data'!D:D,A10,'Working Data'!Y:Y,"Yes")/B10,0) -> 0.095709571 | H10: =IFERROR(AVERAGEIFS('Working Data'!X:X,'Working Data'!D:D,A10,'Working Data'!X:X,"<>"),"") -> 4.0131737
A11: Language Learning | B11: =COUNTIFS('Working Data'!D:D,A11) -> 293 | C11: =SUMIFS('Working Data'!S:S,'Working Data'!D:D,A11) -> 1398842.2 | D11: =SUMIFS('Working Data'!U:U,'Working Data'!D:D,A11) -> 776390.17 | E11: =IFERROR(D11/C11,0) -> 0.55502342 | F11: =IFERROR(COUNTIFS('Working Data'!D:D,A11,'Working Data'!W:W,"Yes")/B11,0) -> 0.58703072 | G11: =IFERROR(COUNTIFS('Working Data'!D:D,A11,'Working Data'!Y:Y,"Yes")/B11,0) -> 0.09556314 | H11: =IFERROR(AVERAGEIFS('Working Data'!X:X,'Working Data'!D:D,A11,'Working Data'!X:X,"<>"),"") -> 3.6386207
A12: Creative Arts | B12: =COUNTIFS('Working Data'!D:D,A12) -> 315 | C12: =SUMIFS('Working Data'!S:S,'Working Data'!D:D,A12) -> 2285702.8 | D12: =SUMIFS('Working Data'!U:U,'Working Data'!D:D,A12) -> 1273862.2 | E12: =IFERROR(D12/C12,0) -> 0.55731752 | F12: =IFERROR(COUNTIFS('Working Data'!D:D,A12,'Working Data'!W:W,"Yes")/B12,0) -> 0.63809524 | G12: =IFERROR(COUNTIFS('Working Data'!D:D,A12,'Working Data'!Y:Y,"Yes")/B12,0) -> 0.092063492 | H12: =IFERROR(AVERAGEIFS('Working Data'!X:X,'Working Data'!D:D,A12,'Working Data'!X:X,"<>"),"") -> 3.7011628
A13: Test Preparation | B13: =COUNTIFS('Working Data'!D:D,A13) -> 316 | C13: =SUMIFS('Working Data'!S:S,'Working Data'!D:D,A13) -> 3048418.5 | D13: =SUMIFS('Working Data'!U:U,'Working Data'!D:D,A13) -> 1698438.2 | E13: =IFERROR(D13/C13,0) -> 0.55715387 | F13: =IFERROR(COUNTIFS('Working Data'!D:D,A13,'Working Data'!W:W,"Yes")/B13,0) -> 0.67088608 | G13: =IFERROR(COUNTIFS('Working Data'!D:D,A13,'Working Data'!Y:Y,"Yes")/B13,0) -> 0.079113924 | H13: =IFERROR(AVERAGEIFS('Working Data'!X:X,'Working Data'!D:D,A13,'Working Data'!X:X,"<>"),"") -> 3.7032787
A16: SECTION 2: Performance by City Tier
A18: City_Tier | B18: Total_Enrollments | C18: Total_Net_Revenue_INR | D18: Total_Gross_Profit_INR | E18: Avg_Margin_% | F18: Completion_Rate_% | G18: Refund_Rate_% | H18: Avg_Rating
A19: Tier 1 | B19: =COUNTIFS('Working Data'!H:H,A19) -> 1055 | C19: =SUMIFS('Working Data'!S:S,'Working Data'!H:H,A19) -> 9501994.9 | D19: =SUMIFS('Working Data'!U:U,'Working Data'!H:H,A19) -> 5669036.1 | E19: =IFERROR(D19/C19,0) -> 0.59661536 | F19: =IFERROR(COUNTIFS('Working Data'!H:H,A19,'Working Data'!W:W,"Yes")/B19,0) -> 0.62559242 | G19: =IFERROR(COUNTIFS('Working Data'!H:H,A19,'Working Data'!Y:Y,"Yes")/B19,0) -> 0.090047393 | H19: =IFERROR(AVERAGEIFS('Working Data'!X:X,'Working Data'!H:H,A19,'Working Data'!X:X,"<>"),"") -> 3.7827338
A20: Tier 2 | B20: =COUNTIFS('Working Data'!H:H,A20) -> 819 | C20: =SUMIFS('Working Data'!S:S,'Working Data'!H:H,A20) -> 7450319.6 | D20: =SUMIFS('Working Data'!U:U,'Working Data'!H:H,A20) -> 4057538.7 | E20: =IFERROR(D20/C20,0) -> 0.54461271 | F20: =IFERROR(COUNTIFS('Working Data'!H:H,A20,'Working Data'!W:W,"Yes")/B20,0) -> 0.64102564 | G20: =IFERROR(COUNTIFS('Working Data'!H:H,A20,'Working Data'!Y:Y,"Yes")/B20,0) -> 0.073260073 | H20: =IFERROR(AVERAGEIFS('Working Data'!X:X,'Working Data'!H:H,A20,'Working Data'!X:X,"<>"),"") -> 3.7365044
A21: Tier 3 | B21: =COUNTIFS('Working Data'!H:H,A21) -> 634 | C21: =SUMIFS('Working Data'!S:S,'Working Data'!H:H,A21) -> 5862770.3 | D21: =SUMIFS('Working Data'!U:U,'Working Data'!H:H,A21) -> 3201020.1 | E21: =IFERROR(D21/C21,0) -> 0.54599105 | F21: =IFERROR(COUNTIFS('Working Data'!H:H,A21,'Working Data'!W:W,"Yes")/B21,0) -> 0.58990536 | G21: =IFERROR(COUNTIFS('Working Data'!H:H,A21,'Working Data'!Y:Y,"Yes")/B21,0) -> 0.11356467 | H21: =IFERROR(AVERAGEIFS('Working Data'!X:X,'Working Data'!H:H,A21,'Working Data'!X:X,"<>"),"") -> 3.7952681

Sheet Project Notes
A1: EdTech India Sales & Completion Analysis — Analyst Documentation
A3: Finding / Step | B3: Detail
A4: Dataset Overview | B4: Synthetic dataset of 2,508 rows (including 8 intentional duplicates) representing student enrollments across 15 EdTech companies, 24 Indian cities, and 8 course categories. Period: Jan 2023 – Dec 2024.
A5: Data Cleaning – Step 1 | B5: Checked for duplicate Enrollment_IDs using Remove Duplicates on column A. Result: 8 duplicates found and removed. Working Data tab used as clean copy; RAW DATA tab protected.
A6: Data Cleaning – Step 2 | B6: Applied TRIM(PROPER()) to City and Company columns to fix 3% upper-case city names and 2% trailing spaces in company names. Formula columns: Cleaned_City, Cleaned_Company.
A7: Missing Values | B7: Student_Rating is blank where: (a) Course_Completed = No, or (b) student opted not to rate (~15% of completers). Decision: left blank; excluded from AVERAGEIFS using '<>' criterion.
A8: Calculated Columns Added | B8: Discount_Category (IFS), Profit_Flag (IF), Month_Year (TEXT+DATEVALUE), Year (YEAR+DATEVALUE), Quarter (CHOOSE+ROUNDUP+MONTH+DATEVALUE).
A9: KPI Cross-Check | B9: SUMIFS-based KPI Summary sheet built independently of Pivot Tables to cross-validate pivot output. Any discrepancy >0.1% flagged for investigation.
A10: Analytical Finding 1 | B10: High-discount (>30%) enrollments show 12pp lower completion rates and negative or near-zero gross margins, suggesting aggressive discounting erodes both revenue quality and student commitment.
A11: Analytical Finding 2 | B11: Coding & Tech leads on margin (58.9%) and completion rate (66.3%), followed by Professional Upskilling (56.4% margin, 63.1% completion). K-12 Academics has the lowest completion rate (60.1%) among categories, though margins are broadly similar (54-59%) across all categories.
A12: Analytical Finding 3 | B12: Tier 2 and Tier 3 cities show 6-8% lower completion rates but comparable refund rates to Tier 1, suggesting infrastructure/connectivity may be a barrier rather than dissatisfaction.
A13: Data Source Note | B13: Dataset is synthetically generated to reflect realistic Indian EdTech market patterns (pricing, GST structure, city-tier distribution, course mix). Not proprietary data.
